<?xml version="1.0" ?>
<robot name="jettank">
  <material name="black">
    <color rgba="0.1 0.1 0.1 1.0"/>
  </material>
  <material name="green">
    <color rgba="0.4 0.9 0.4 1.0"/>
  </material>

  <!-- Base Footprint -->
  <link name="base_footprint"/>
  <joint name="base_joint" type="fixed">
    <parent link="base_footprint"/>
    <child link="base_link"/>
    <origin rpy="0 0 0" xyz="0.0 0.0 0.05"/>
  </joint>

  <!-- Base Link (Chassis) -->
  <link name="base_link">
    <inertial>
      <mass value="1.6"/>
      <inertia ixx="0.00449" ixy="0" ixz="0" iyy="0.01345" iyz="0" izz="0.01456"/>
    </inertial>
    <visual>
      <geometry>
        <box size="0.297 0.145 0.11255"/>
      </geometry>
      <material name="green"/>
    </visual>
    <collision>
      <geometry>
        <box size="0.297 0.145 0.11255"/>
      </geometry>
    </collision>
  </link>

  <!-- Left Wheel -->
  <link name="left_wheel">
    <inertial>
      <mass value="0.1"/>
      <inertia ixx="0.0001" ixy="0" ixz="0" iyy="0.0001" iyz="0" izz="0.0001"/>
    </inertial>
    <visual>
      <origin rpy="1.570796 0 0" xyz="0 0 0"/>
      <geometry>
        <cylinder length="0.04" radius="0.05"/>
      </geometry>
      <material name="black"/>
    </visual>
    <collision>
      <origin rpy="1.570796 0 0" xyz="0 0 0"/>
      <geometry>
        <cylinder length="0.04" radius="0.05"/>
      </geometry>
    </collision>
  </link>

  <joint name="left_wheel_joint" type="continuous">
    <parent link="base_link"/>
    <child link="left_wheel"/>
    <origin rpy="0 0 0" xyz="0.1 0.08 -0.025"/>
    <axis xyz="0 1 0"/>
  </joint>

  <!-- Right Wheel -->
  <link name="right_wheel">
    <inertial>
      <mass value="0.1"/>
      <inertia ixx="0.0001" ixy="0" ixz="0" iyy="0.0001" iyz="0" izz="0.0001"/>
    </inertial>
    <visual>
      <origin rpy="1.570796 0 0" xyz="0 0 0"/>
      <geometry>
        <cylinder length="0.04" radius="0.05"/>
      </geometry>
      <material name="black"/>
    </visual>
    <collision>
      <origin rpy="1.570796 0 0" xyz="0 0 0"/>
      <geometry>
        <cylinder length="0.04" radius="0.05"/>
      </geometry>
    </collision>
  </link>

  <joint name="right_wheel_joint" type="continuous">
    <parent link="base_link"/>
    <child link="right_wheel"/>
    <origin rpy="0 0 0" xyz="0.1 -0.08 -0.025"/>
    <axis xyz="0 1 0"/>
  </joint>

  <!-- Lidar (Simplified) -->
  <link name="lidar_link">
    <visual>
      <geometry>
        <cylinder length="0.03" radius="0.03"/>
      </geometry>
      <material name="black"/>
    </visual>
  </link>
  <joint name="lidar_joint" type="fixed">
    <parent link="base_link"/>
    <child link="lidar_link"/>
    <origin xyz="0.1 0 0.1" rpy="0 0 0"/>
  </joint>

  <!-- Camera (Simplified) -->
  <link name="camera_link">
    <visual>
      <geometry>
        <box size="0.02 0.05 0.02"/>
      </geometry>
      <material name="black"/>
    </visual>
  </link>
  <joint name="camera_joint" type="fixed">
    <parent link="base_link"/>
    <child link="camera_link"/>
    <origin xyz="0.14 0 0.05" rpy="0 0 0"/>
  </joint>

</robot>
