<?xml version="1.0" ?>
<!-- =================================================================================== -->
<!-- |    This document was autogenerated by xacro from jettank.xacro                  | -->
<!-- |    EDITING THIS FILE BY HAND IS NOT RECOMMENDED                                 | -->
<!-- =================================================================================== -->
<robot name="jettank">
  <material name="black">
    <color rgba="0.1 0.1 0.1 1.0"/>
  </material>
  <material name="blue">
    <color rgba="0.0 0.0 0.8 1.0"/>
  </material>
  <material name="green">
    <color rgba="0.4 0.9 0.4 1.0"/>
  </material>
  <material name="gray">
    <color rgba="0.7 0.7 0.7 1.0"/>
  </material>
  <material name="darkgray">
    <color rgba="0.3 0.3 0.3 1.0"/>
  </material>
  <material name="red">
    <color rgba="0.8 0.0 0.0 1.0"/>
  </material>
  <material name="white">
    <color rgba="1.0 1.0 1.0 1.0"/>
  </material>
  <material name="yellow">
    <color rgba="0.8 0.8 0.0 1.0"/>
  </material>
  <link name="imu_link"/>
  <joint name="imu_joint" type="fixed">
    <origin rpy="0 0 3.141592653589793" xyz="-0.08489999999999998 0 0.080963557909225"/>
    <parent link="base_link"/>
    <child link="imu_link"/>
  </joint>
  <link name="lidar_link">
    <inertial>
      <origin rpy="0 0 0" xyz="-0.0157049024536227 0.000340793431659825 -0.0214732100882973"/>
      <mass value="0.0522535578752524"/>
      <inertia ixx="1.4542908499666E-05" ixy="4.8193721668021E-08" ixz="2.30575406031324E-07" iyy="1.85618648837978E-05" iyz="-1.29750110413905E-08" izz="3.10574357987674E-05"/>
    </inertial>
    <visual>
      <origin rpy="0 0 0" xyz="0 0 0"/>
      <geometry>
        <mesh filename="/workspace/IsaacLab/source/extensions/pinn_nav/pinn_nav/assets/meshes/lidar_link.stl"/>
      </geometry>
      <material name="black"/>
    </visual>
    <collision>
      <origin rpy="0 0 0" xyz="0 0 0"/>
      <geometry>
        <mesh filename="/workspace/IsaacLab/source/extensions/pinn_nav/pinn_nav/assets/meshes/lidar_link.stl"/>
      </geometry>
    </collision>
  </link>
  <joint name="lidar_joint" type="fixed">
    <origin rpy="0 0 0" xyz="0.0959394346777203 -1.03974386779226E-05 0.128396206697751"/>
    <parent link="base_link"/>
    <child link="lidar_link"/>
    <axis xyz="0 0 0"/>
  </joint>
  <link name="lidar_frame"/>
  <joint name="lidar_frame_joint" type="fixed">
    <origin rpy="0 0 3.141592653589793" xyz="0 0 0"/>
    <parent link="lidar_link"/>
    <child link="lidar_frame"/>
  </joint>
  <link name="camera_link">
    <inertial>
      <origin rpy="0 0 0" xyz="0.000254340878565573 0.00268031633059271 -0.00569075323067275"/>
      <mass value="0.227980406655671"/>
      <inertia ixx="4.8473190489023E-05" ixy="8.29314946303069E-09" ixz="-5.0952649884666E-09" iyy="0.000408820027771005" iyz="-1.36580074559918E-07" izz="0.000429553467348926"/>
    </inertial>
    <visual>
      <origin rpy="0 0 1.57" xyz="0 0 0"/>
      <geometry>
        <mesh filename="/workspace/IsaacLab/source/extensions/pinn_nav/pinn_nav/assets/meshes/depth_camera_link.stl"/>
      </geometry>
      <material name="black"/>
    </visual>
    <collision>
      <origin rpy="0 0 1.57" xyz="0 0 0"/>
      <geometry>
        <mesh filename="/workspace/IsaacLab/source/extensions/pinn_nav/pinn_nav/assets/meshes/depth_camera_link.stl"/>
      </geometry>
    </collision>
  </link>
  <joint name="joint1" type="revolute">
    <origin rpy="-0.000131510931722419 0 0" xyz="0.0288581470059471 0 0.202093286991617"/>
    <parent link="base_link"/>
    <child link="camera_link"/>
    <axis xyz="0 0 1"/>
    <limit effort="1000" lower="-2.09" upper="2.09" velocity="10"/>
  </joint>
  <link name="camera_frame"/>
  <joint name="camera_joint_sim" type="fixed">
    <origin rpy="-1.5707963267948966 0 -1.5707963267948966" xyz="0 0 0"/>
    <parent link="camera_link"/>
    <child link="camera_frame"/>
  </joint>
  <link name="base_footprint"/>
  <joint name="base_joint" type="fixed">
    <parent link="base_footprint"/>
    <child link="base_link"/>
    <origin rpy="0 0 0" xyz="0.0 0.0 0.0"/>
  </joint>
  <link name="base_link">
    <inertial>
      <mass value="1.6"/>
      <inertia ixx="0.004492333666666667" ixy="0" ixz="0" iyy="0.013450200333333334" iyz="0" izz="0.014564533333333332"/>
    </inertial>
    <visual>
      <origin rpy="0 0 0" xyz="0 0 0"/>
      <geometry>
        <mesh filename="../meshes/base_link.stl"/>
      </geometry>
      <material name="green"/>
    </visual>
    <collision>
      <origin rpy="0 0 0" xyz="0.0003999999999999837 0 0.08684214"/>
      <geometry>
        <box size="0.297 0.145 0.11255"/>
      </geometry>
    </collision>
  </link>
  <link name="wheel_link">
    <inertial>
      <origin rpy="0 0 0" xyz="0 0 0"/>
      <mass value="0.0663478534899862"/>
      <inertia ixx="5.65277934912267E-05" ixy="-5.13394387877366E-11" ixz="-4.07561372273553E-11" iyy="4.33740893441632E-05" iyz="-5.43059341238134E-06" izz="6.86642544694324E-05"/>
    </inertial>
    <visual>
      <origin rpy="0 0 0" xyz="0 0 0"/>
      <geometry>
        <mesh filename="/workspace/IsaacLab/source/extensions/pinn_nav/pinn_nav/assets/meshes/wheel.stl"/>
      </geometry>
      <material name="black">
      </material>
    </visual>
    <collision>
      <origin rpy="0 0 0" xyz="0 0 0"/>
      <geometry>
        <mesh filename="/workspace/IsaacLab/source/extensions/pinn_nav/pinn_nav/assets/meshes/wheel.stl"/>
      </geometry>
    </collision>
  </link>
  <joint name="wheel_joint" type="fixed">
    <origin rpy="0 0 0" xyz="0 0 0"/>
    <parent link="base_link"/>
    <child link="wheel_link"/>
    <axis xyz="0 0 0"/>
  </joint>
  <link name="back_shell_link">
    <inertial>
      <origin rpy="0 0 0" xyz="-1.22838595456587E-05 0.00218574826309681 -0.0500522861933898"/>
      <mass value="0.0663478534899862"/>
      <inertia ixx="5.65277934912267E-05" ixy="-5.13394387877366E-11" ixz="-4.07561372273553E-11" iyy="4.33740893441632E-05" iyz="-5.43059341238134E-06" izz="6.86642544694324E-05"/>
    </inertial>
    <visual>
      <origin rpy="0 0 0" xyz="0 0.01 0"/>
      <geometry>
        <mesh filename="/workspace/IsaacLab/source/extensions/pinn_nav/pinn_nav/assets/meshes/back_shell_link.stl"/>
      </geometry>
      <material name="black">
      </material>
    </visual>
    <collision>
      <origin rpy="0 0 0" xyz="0 0 0"/>
      <geometry>
        <mesh filename="/workspace/IsaacLab/source/extensions/pinn_nav/pinn_nav/assets/meshes/back_shell_link.stl"/>
      </geometry>
    </collision>
  </link>
  <joint name="back_shell_joint" type="fixed">
    <origin rpy="-3.1416 0 1.5708" xyz="-0.076481 0 0.082796"/>
    <parent link="base_link"/>
    <child link="back_shell_link"/>
    <axis xyz="0 0 0"/>
  </joint>
  <transmission name="tran_joint1">
    <type>transmission_interface/SimpleTransmission</type>
    <joint name="joint1">
      <hardwareInterface>hardware_interface/PositionJointInterface</hardwareInterface>
    </joint>
    <actuator name="joint1_motor">
      <hardwareInterface>hardware_interface/PositionJointInterface</hardwareInterface>
      <mechanicalReduction>1</mechanicalReduction>
    </actuator>
  </transmission>
  <gazebo>
    <plugin filename="libgazebo_ros_control.so" name="gazebo_ros_control"/>
  </gazebo>
</robot>
